<?xml version="1.0" encoding="utf-8"?>
<!-- URDF cleaned and wheel names aligned with ros2_control -->
<robot name="ct">
  <link name="base_link">
    <inertial>
      <origin xyz="0.723898474040511 -1.37403577535756 0.970388088854667" rpy="0 0 0" />
      <mass value="0.249821153529968" />
      <inertia ixx="0.000871705475246986" ixy="2.76752495563273E-09" ixz="-1.20236732648511E-08"
               iyy="0.00327890389176736" iyz="-9.15021692461746E-09" izz="0.00408901712005288" />
    </inertial>
    <visual>
      <origin xyz="0 0 0" rpy="0 0 0" />
      <geometry>
        <mesh filename="package://Odometry FIle/meshes/base_link.STL" />
      </geometry>
      <material name="">
        <color rgba="0.792156862745098 0.819607843137255 0.933333333333333 1" />
      </material>
    </visual>
    <collision>
      <origin xyz="0 0 0" rpy="0 0 0" />
      <geometry>
        <mesh filename="package://Odometry FIle/meshes/base_link.STL" />
      </geometry>
    </collision>  
  </link>

  <!-- Front Left Wheel -->
  <link name="front_left_wheel_link">
    <inertial>
      <origin xyz="0 0 0.0225" rpy="0 0 0" />
      <mass value="0.224922326033761" />
      <inertia ixx="0.000128430648165277" ixy="0" ixz="0"
               iyy="0.000128430648165277" iyz="0" izz="0.000180950011294161" />
    </inertial>
    <visual>
      <origin xyz="0 0 0" rpy="0 0 0" />
      <geometry>
        <mesh filename="package://Odometry FIle/meshes/Wheel1.STL" />
      </geometry>
    </visual>
    <collision>
      <origin xyz="0 0 0" rpy="0 0 0" />
      <geometry>
        <mesh filename="package://Odometry FIle/meshes/Wheel1.STL" />
      </geometry>
    </collision>
  </link>
  <joint name="front_left_wheel_joint" type="continuous">
    <origin xyz="0.56391 -1.444 0.99365" rpy="1.5708 0.013855 0" />
    <parent link="base_link" />
    <child link="front_left_wheel_link" />
    <axis xyz="0 0 1" />
  </joint>

  <!-- Front Right Wheel -->
  <link name="front_right_wheel_link">
    <inertial>
      <origin xyz="0 0 0.0225" rpy="0 0 0" />
      <mass value="0.224922326033761" />
      <inertia ixx="0.000128430648165277" ixy="0" ixz="0"
               iyy="0.000128430648165277" iyz="0" izz="0.000180950011294161" />
    </inertial>
    <visual>
      <origin xyz="0 0 0" rpy="0 0 0" />
      <geometry>
        <mesh filename="package://Odometry FIle/meshes/Wheel2.STL" />
      </geometry>
    </visual>
    <collision>
      <origin xyz="0 0 0" rpy="0 0 0" />
      <geometry>
        <mesh filename="package://Odometry FIle/meshes/Wheel2.STL" />
      </geometry>
    </collision>
  </link>
  <joint name="front_right_wheel_joint" type="continuous">
    <origin xyz="0.56391 -1.259 0.99365" rpy="-1.5708 0.38576 -3.1416" />
    <parent link="base_link" />
    <child link="front_right_wheel_link" />
    <axis xyz="0 0 1" />
  </joint>

  <!-- Rear Left Wheel -->
  <link name="rear_left_wheel_link">
    <inertial>
      <origin xyz="0 0 0.0225" rpy="0 0 0" />
      <mass value="0.224922326033761" />
      <inertia ixx="0.000128430648165277" ixy="0" ixz="0"
               iyy="0.000128430648165277" iyz="0" izz="0.000180950011294161" />
    </inertial>
    <visual>
      <origin xyz="0 0 0" rpy="0 0 0" />
      <geometry>
        <mesh filename="package://Odometry FIle/meshes/Wheel3.STL" />
      </geometry>
    </visual>
    <collision>
      <origin xyz="0 0 0" rpy="0 0 0" />
      <geometry>
        <mesh filename="package://Odometry FIle/meshes/Wheel3.STL" />
      </geometry>
    </collision>
  </link>
  <joint name="rear_left_wheel_joint" type="continuous">
    <origin xyz="0.88391 -1.444 0.99365" rpy="1.5708 -0.17346 0" />
    <parent link="base_link" />
    <child link="rear_left_wheel_link" />
    <axis xyz="0 0 1" />
  </joint>

  <!-- Rear Right Wheel -->
  <link name="rear_right_wheel_link">
    <inertial>
      <origin xyz="0 0 0.0225" rpy="0 0 0" />
      <mass value="0.224922326033761" />
      <inertia ixx="0.000128430648165277" ixy="0" ixz="0"
               iyy="0.000128430648165277" iyz="0" izz="0.000180950011294161" />
    </inertial>
    <visual>
      <origin xyz="0 0 0" rpy="0 0 0" />
      <geometry>
        <mesh filename="package://Odometry FIle/meshes/Wheel4.STL" />
      </geometry>
    </visual>
    <collision>
      <origin xyz="0 0 0" rpy="0 0 0" />
      <geometry>
        <mesh filename="package://Odometry FIle/meshes/Wheel4.STL" />
      </geometry>
    </collision>
  </link>
  <joint name="rear_right_wheel_joint" type="continuous">
    <origin xyz="0.88391 -1.259 0.99365" rpy="1.5708 -0.073815 0" />
    <parent link="base_link" />
    <child link="rear_right_wheel_link" />
    <axis xyz="0 0 1" />
  </joint>

  <!-- Lidar -->
  <link name="taitc_lidar_link">
    <inertial>
      <origin xyz="0 0.0125 0" rpy="0 0 0" />
      <mass value="0.0962112750161875" />
      <inertia ixx="3.44757068808006E-05" ixy="0" ixz="0"
               iyy="5.89294059474149E-05" iyz="0" izz="3.44757068808006E-05" />
    </inertial>
    <visual>
      <origin xyz="0 0 0" rpy="0 0 0" />
      <geometry>
        <mesh filename="package://Odometry FIle/meshes/taitc_lidar_link.STL" />
      </geometry>
    </visual>
    <collision>
      <origin xyz="0 0 0" rpy="0 0 0" />
      <geometry>
        <mesh filename="package://Odometry FIle/meshes/taitc_lidar_link.STL" />
      </geometry>
    </collision>
  </link>
  <joint name="taitc_lidar_joint" type="fixed">
    <origin xyz="0.708399374631133 -1.37350613548206 0.854171401767211" rpy="0 0 0" />
    <parent link="base_link"/>
    <child link="taitc_lidar_link"/>
  </joint>

  <!-- ros2_control interfaces already aligned -->
  <ros2_control name="ct_robot" type="system">
    <hardware>
      <plugin>mock_components/GenericSystem</plugin>
    </hardware>
    <joint name="front_left_wheel_joint">
      <command_interface name="velocity"/>
      <state_interface name="position"/>
      <state_interface name="velocity"/>
    </joint>
    <joint name="front_right_wheel_joint">
      <command_interface name="velocity"/>
      <state_interface name="position"/>
      <state_interface name="velocity"/>
    </joint>
    <joint name="rear_left_wheel_joint">
      <command_interface name="velocity"/>
      <state_interface name="position"/>
      <state_interface name="velocity"/>
    </joint>
    <joint name="rear_right_wheel_joint">
      <command_interface name="velocity"/>
      <state_interface name="position"/>
      <state_interface name="velocity"/>
    </joint>
  </ros2_control>
</robot>
